<sdf version="1.7">
  <world name="office">
    <scene>
      <ambient>0.8 0.8 0.8 1.0</ambient>
      <background>0 0 0</background>
      <grid>false</grid>
    </scene>
    <include>
      <uri>model://sun</uri>
    </include>
    <gui>
      <camera name="gui_camera">
        <pose>14.436225404387812 -23.629919563307524 10 0 0.6 1.57</pose>
      </camera>
    </gui>
    <include>
      <name>OfficeChairBlack</name>
      <uri>model://OfficeChairBlack</uri>
      <pose>6.562113035969731 -6.72165375308089 0.0 0 0 4.2503</pose>
      <static>True</static>
    </include>
    <include>
      <name>OfficeChairBlack_2</name>
      <uri>model://OfficeChairBlack</uri>
      <pose>6.239069750128609 -7.483497502189539 0.0 0 0 4.2239</pose>
      <static>True</static>
    </include>
    <include>
      <name>OfficeChairBlack_3</name>
      <uri>model://OfficeChairBlack</uri>
      <pose>5.758449741995906 -8.260443694221157 0.0 0 0 4.247</pose>
      <static>True</static>
    </include>
    <include>
      <name>OfficeChairBlack_4</name>
      <uri>model://OfficeChairBlack</uri>
      <pose>5.395881060410753 -9.02572443426407 0.0 0 0 4.2458</pose>
      <static>True</static>
    </include>
    <include>
      <name>OfficeChairBlack_5</name>
      <uri>model://OfficeChairBlack</uri>
      <pose>3.8721597002138073 -8.264828820585564 0.0 0 0 1.0926</pose>
      <static>True</static>
    </include>
    <include>
      <name>OfficeChairBlack_6</name>
      <uri>model://OfficeChairBlack</uri>
      <pose>4.26201267190027 -7.489812761393875 0.0 0 0 1.1213</pose>
      <static>True</static>
    </include>
    <include>
      <name>OfficeChairBlack_7</name>
      <uri>model://OfficeChairBlack</uri>
      <pose>4.652678331098282 -6.752375034116462 0.0 0 0 1.0613</pose>
      <static>True</static>
    </include>
    <include>
      <name>OfficeChairBlack_8</name>
      <uri>model://OfficeChairBlack</uri>
      <pose>5.0126227092607225 -6.058839363452574 0.0 0 0 1.0779</pose>
      <static>True</static>
    </include>
    <include>
      <name>Fridge</name>
      <uri>model://Fridge</uri>
      <pose>15.905877648581944 -5.753531289452046 0.0 0 0 1.5708</pose>
      <static>True</static>
    </include>
    <include>
      <name>OfficeChairGrey</name>
      <uri>model://OfficeChairGrey</uri>
      <pose>14.25575798385424 -5.546939351620108 0.0 0 0 0.0166</pose>
      <static>True</static>
    </include>
    <include>
      <name>AdjTable</name>
      <uri>model://AdjTable</uri>
      <pose>11.788455629778278 -5.979746244489952 0.0 0 0 3.1613</pose>
      <static>True</static>
    </include>
    <include>
      <name>AdjTable_2</name>
      <uri>model://AdjTable</uri>
      <pose>8.395375217623192 -4.354184980501898 0.0 0 0 1.099</pose>
      <static>True</static>
    </include>
    <include>
      <name>AdjTable_3</name>
      <uri>model://AdjTable</uri>
      <pose>14.244879822892347 -5.941482207487806 0.0 0 0 3.1594</pose>
      <static>True</static>
    </include>
    <include>
      <name>SmallCubicle</name>
      <uri>model://SmallCubicle</uri>
      <pose>10.225911509914997 -8.526615785243605 0.0 0 0 1.5708</pose>
      <static>True</static>
    </include>
    <include>
      <name>SmallCubicle_2</name>
      <uri>model://SmallCubicle</uri>
      <pose>10.183296208528093 -9.890381619078704 0.0 0 0 1.5708</pose>
      <static>True</static>
    </include>
    <include>
      <name>SmallCubicle_3</name>
      <uri>model://SmallCubicle</uri>
      <pose>13.810743847321321 -9.831106223705028 0.0 0 0 1.5708</pose>
      <static>True</static>
    </include>
    <include>
      <name>SmallCubicle_4</name>
      <uri>model://SmallCubicle</uri>
      <pose>9.391493072925952 -8.541963727519024 0.0 0 0 -1.5708</pose>
      <static>True</static>
    </include>
    <include>
      <name>SmallCubicle_5</name>
      <uri>model://SmallCubicle</uri>
      <pose>9.36992299189023 -9.890178447200816 0.0 0 0 4.7124</pose>
      <static>True</static>
    </include>
    <include>
      <name>SmallCubicle_6</name>
      <uri>model://SmallCubicle</uri>
      <pose>12.9440464782329 -9.827406802428492 0.0 0 0 4.7124</pose>
      <static>True</static>
    </include>
    <include>
      <name>SmallCubicle_7</name>
      <uri>model://SmallCubicle</uri>
      <pose>12.955153207557416 -8.471810171183453 0.0 0 0 -1.5708</pose>
      <static>True</static>
    </include>
    <include>
      <name>SmallCubicle_8</name>
      <uri>model://SmallCubicle</uri>
      <pose>13.810743847321321 -8.460694976364024 0.0 0 0 1.5708</pose>
      <static>True</static>
    </include>
    <include>
      <name>AdjTable_4</name>
      <uri>model://AdjTable</uri>
      <pose>6.734191151045531 -9.675341117324612 0.0 0 0 1.0878</pose>
      <static>True</static>
    </include>
    <include>
      <name>Drawer</name>
      <uri>model://Drawer</uri>
      <pose>6.166080252997525 -10.553500766523852 0.0 0 0 1.1104</pose>
      <static>True</static>
    </include>
    <include>
      <name>BigCubicle</name>
      <uri>model://BigCubicle</uri>
      <pose>17.404769712202054 -8.093766564899202 0.0 0 0 1.6279</pose>
      <static>True</static>
    </include>
    <include>
      <name>BigCubicle_2</name>
      <uri>model://BigCubicle</uri>
      <pose>17.37541984134222 -9.551473995772533 0.0 0 0 1.5708</pose>
      <static>True</static>
    </include>
    <include>
      <name>BigCubicle_3</name>
      <uri>model://BigCubicle</uri>
      <pose>16.495355455787788 -9.581348727316906 0.0 0 0 -1.5708</pose>
      <static>True</static>
    </include>
    <include>
      <name>BigCubicle_4</name>
      <uri>model://BigCubicle</uri>
      <pose>16.513429287424863 -8.135924729560857 0.0 0 0 1.6108</pose>
      <static>True</static>
    </include>
    <include>
      <name>AdjTable_5</name>
      <uri>model://AdjTable</uri>
      <pose>22.074836169849544 -10.32024251971918 0.0 0 0 4.6088</pose>
      <static>True</static>
    </include>
    <include>
      <name>AdjTable_6</name>
      <uri>model://AdjTable</uri>
      <pose>22.382768547272782 -7.585083441133288 0.0 0 0 4.5816</pose>
      <static>True</static>
    </include>
    <include>
      <name>AdjTable_7</name>
      <uri>model://AdjTable</uri>
      <pose>19.933099819098473 -7.193799800806701 0.0 0 0 1.5733</pose>
      <static>True</static>
    </include>
    <include>
      <name>AdjTable_8</name>
      <uri>model://AdjTable</uri>
      <pose>7.47503200727756 -3.868731174774456 0.0 0 0 4.2286</pose>
      <static>True</static>
    </include>
    <include>
      <name>AdjTable_9</name>
      <uri>model://AdjTable</uri>
      <pose>13.006471037713835 -5.565732750324702 0.0 0 0 1.5914</pose>
      <static>True</static>
    </include>
    <include>
      <name>OfficeChairGrey_2</name>
      <uri>model://OfficeChairGrey</uri>
      <pose>22.657389202217384 -3.444372845826767 0.0 0 0 1.8623</pose>
      <static>True</static>
    </include>
    <include>
      <name>OfficeChairGrey_3</name>
      <uri>model://OfficeChairGrey</uri>
      <pose>22.423335198890985 -4.614642862458759 0.0 0 0 1.4219</pose>
      <static>True</static>
    </include>
    <include>
      <name>OfficeChairGrey_4</name>
      <uri>model://OfficeChairGrey</uri>
      <pose>14.205616857490586 -8.518074100877419 0.0 0 0 -1.5708</pose>
      <static>True</static>
    </include>
    <include>
      <name>OfficeChairGrey_5</name>
      <uri>model://OfficeChairGrey</uri>
      <pose>21.993355781321743 -7.517359481837455 0.0 0 0 1.419</pose>
      <static>True</static>
    </include>
    <include>
      <name>OfficeChairGrey_6</name>
      <uri>model://OfficeChairGrey</uri>
      <pose>21.731416437755286 -10.29278045422472 0.0 0 0 1.4599</pose>
      <static>True</static>
    </include>
    <include>
      <name>OfficeChairBlue</name>
      <uri>model://OfficeChairBlue</uri>
      <pose>8.87747668736549 -8.63695504592634 0.0 0 0 1.5708</pose>
      <static>True</static>
    </include>
    <include>
      <name>OfficeChairBlue_2</name>
      <uri>model://OfficeChairBlue</uri>
      <pose>8.853637853693357 -9.784393622780726 0.0 0 0 1.5708</pose>
      <static>True</static>
    </include>
    <include>
      <name>OfficeChairBlue_3</name>
      <uri>model://OfficeChairBlue</uri>
      <pose>10.702933682710107 -8.503742017991438 0.0 0 0 4.7124</pose>
      <static>True</static>
    </include>
    <include>
      <name>OfficeChairBlue_4</name>
      <uri>model://OfficeChairBlue</uri>
      <pose>10.698159143579753 -9.870411516581347 0.0 0 0 4.7124</pose>
      <static>True</static>
    </include>
    <include>
      <name>OfficeChairBlue_5</name>
      <uri>model://OfficeChairBlue</uri>
      <pose>12.456662539665526 -8.470294847594209 0.0 0 0 1.5708</pose>
      <static>True</static>
    </include>
    <include>
      <name>OfficeChairBlue_6</name>
      <uri>model://OfficeChairBlue</uri>
      <pose>14.310741373307545 -9.832181341558849 0.0 0 0 -1.5708</pose>
      <static>True</static>
    </include>
    <include>
      <name>OfficeChairBlue_7</name>
      <uri>model://OfficeChairBlue</uri>
      <pose>16.02188879085571 -9.773041394103762 0.0 0 0 1.5708</pose>
      <static>True</static>
    </include>
    <include>
      <name>OfficeChairBlue_8</name>
      <uri>model://OfficeChairBlue</uri>
      <pose>16.041003878366954 -8.435044526780727 0.0 0 0 1.5708</pose>
      <static>True</static>
    </include>
    <include>
      <name>OfficeChairBlue_9</name>
      <uri>model://OfficeChairBlue</uri>
      <pose>17.804290279077996 -8.544952047222951 0.0 0 0 -1.5708</pose>
      <static>True</static>
    </include>
    <include>
      <name>OfficeChairBlue_10</name>
      <uri>model://OfficeChairBlue</uri>
      <pose>17.83296291034487 -9.72525367532564 0.0 0 0 -1.5708</pose>
      <static>True</static>
    </include>
    <include>
      <name>OfficeChairBlack_9</name>
      <uri>model://OfficeChairBlack</uri>
      <pose>12.394542738001423 -9.712716277360999 0.0 0 0 1.5708</pose>
      <static>True</static>
    </include>
    <include>
      <name>OfficeChairGrey_7</name>
      <uri>model://OfficeChairGrey</uri>
      <pose>11.842888762062305 -5.564640701481056 0.0 0 0 0.016</pose>
      <static>True</static>
    </include>
    <include>
      <name>Drawer_2</name>
      <uri>model://Drawer</uri>
      <pose>17.944157186013715 -7.932151801534608 0.0 0 0 1.5708</pose>
      <static>True</static>
    </include>
    <include>
      <name>Drawer_3</name>
      <uri>model://Drawer</uri>
      <pose>22.225716685665745 -9.267287331577394 0.0 0 0 4.6217</pose>
      <static>True</static>
    </include>
    <include>
      <name>ConfTable</name>
      <uri>model://ConfTable</uri>
      <pose>5.248606845427052 -7.381911563245789 0.0 0 0 1.1017</pose>
      <static>True</static>
    </include>
    <include>
      <name>WhiteCabinet</name>
      <uri>model://WhiteCabinet</uri>
      <pose>15.03369463879056 -2.9190973520333747 0.0 0 0 -0.0357</pose>
      <static>True</static>
    </include>
    <include>
      <name>file_dispenser</name>
      <uri>model://TeleportDispenser</uri>
      <pose>17.75523273606308 -5.500954783258237 1.08 0 0 1.5708</pose>
      <static>True</static>
    </include>
    <include>
      <name>file_dispenser_2</name>
      <uri>model://TeleportDispenser</uri>
      <pose>17.737472127737746 -5.839032788063036 0.63 0 0 1.5708</pose>
      <static>True</static>
    </include>
    <include>
      <name>FileBox</name>
      <uri>model://file_box_1</uri>
      <pose>17.766119362519884 -5.5069991466253905 1.08 0 0 1.5708</pose>
      <static>False</static>
    </include>
    <include>
      <name>file_ingestor</name>
      <uri>model://TeleportIngestor</uri>
      <pose>22.542656349675333 -7.610446063889577 0.805 0 0 1.5708</pose>
      <static>True</static>
    </include>
    <include>
      <name>file_ingestor_2</name>
      <uri>model://TeleportIngestor</uri>
      <pose>5.661375911840242 -5.958557110725269 0.8 0 0 1.5708</pose>
      <static>True</static>
    </include>
    <include>
      <name>OpenRobotics/MetalCabinet</name>
      <uri>model://MetalCabinet</uri>
      <pose>16.474310235436608 -10.48782545699672 0.0 0 0 0.0093</pose>
      <static>True</static>
    </include>
    <include>
      <name>OpenRobotics/MetalCabinet_2</name>
      <uri>model://MetalCabinet</uri>
      <pose>17.385485314792568 -10.477751518051464 0.0 0 0 0.0172</pose>
      <static>True</static>
    </include>
    <include>
      <name>OpenRobotics/SquareShelf</name>
      <uri>model://SquareShelf</uri>
      <pose>20.748470892535565 -3.0699101438902825 0.0 0 0 -0.0083</pose>
      <static>True</static>
    </include>
    <include>
      <name>OpenRobotics/Fridge</name>
      <uri>model://Fridge</uri>
      <pose>15.881073748489847 -5.114826629333046 0.0 0 0 1.5708</pose>
      <static>True</static>
    </include>
    <include>
      <name>OpenRobotics/AdjTable</name>
      <uri>model://AdjTable</uri>
      <pose>22.852434204989382 -4.62764586264356 0.0 0 0 -1.7435</pose>
      <static>True</static>
    </include>
    <include>
      <name>OpenRobotics/CoffeeTable</name>
      <uri>model://CoffeeTable</uri>
      <pose>23.134165875660052 -3.3360145109534343 0.0 0 0 1.5708</pose>
      <static>True</static>
    </include>
    <include>
      <name>OpenRobotics/Drawer</name>
      <uri>model://Drawer</uri>
      <pose>8.732538948977497 -3.365973897446928 0.0 0 0 1.178</pose>
      <static>True</static>
    </include>
    <include>
      <name>OpenRobotics/SquareShelf_2</name>
      <uri>model://SquareShelf</uri>
      <pose>22.52421850175704 -5.690514145327274 0.0 0 0 0.0286</pose>
      <static>True</static>
    </include>
    <include>
      <name>OpenRobotics/TrashBin</name>
      <uri>model://TrashBin</uri>
      <pose>12.793360668799671 -7.634267966571886 0.0 0 0 1.5708</pose>
      <static>True</static>
    </include>
    <include>
      <name>OpenRobotics/TrashBin_2</name>
      <uri>model://TrashBin</uri>
      <pose>13.18875853965348 -7.634267966571886 0.0 0 0 1.5708</pose>
      <static>True</static>
    </include>
    <include>
      <name>OpenRobotics/TrashBin_3</name>
      <uri>model://TrashBin</uri>
      <pose>13.584147945012376 -7.63886473030909 0.0 0 0 1.5708</pose>
      <static>True</static>
    </include>
    <include>
      <name>OpenRobotics/WhiteCabinet</name>
      <uri>model://WhiteCabinet</uri>
      <pose>17.727423585277226 -5.139376564577785 0.0 0 0 -1.564</pose>
      <static>True</static>
    </include>
    <include>
      <name>OpenRobotics/Drawer_2</name>
      <uri>model://Drawer</uri>
      <pose>17.746597931252857 -5.807727387878537 0.0 0 0 -1.5751</pose>
      <static>True</static>
    </include>
    <include>
      <name>OpenRobotics/MetalCabinetYellow</name>
      <uri>model://MetalCabinetYellow</uri>
      <pose>21.690604286784634 -3.4578245172419018 0.0 0 0 -0.0435</pose>
      <static>True</static>
    </include>
    <include>
      <name>OpenRobotics/MetalCabinet_3</name>
      <uri>model://MetalCabinet</uri>
      <pose>6.425048207849878 -3.986537001969557 0.0 0 0 2.6834</pose>
      <static>True</static>
    </include>
    <include>
      <name>OpenRobotics/MetalCabinet_4</name>
      <uri>model://MetalCabinet</uri>
      <pose>5.894811934038065 -3.145168393657777 0.0 0 0 1.1071</pose>
      <static>True</static>
    </include>
    <include>
      <name>OpenRobotics/OfficeChairBlue</name>
      <uri>model://OfficeChairBlue</uri>
      <pose>7.135413282398781 -9.977906370973656 0.0 0 0 -2.0863</pose>
      <static>True</static>
    </include>
    <include>
      <name>OpenRobotics/MetalCabinet_5</name>
      <uri>model://MetalCabinet</uri>
      <pose>20.85271499688168 -6.417945657618727 0.0 0 0 -0.0145</pose>
      <static>True</static>
    </include>
    <include>
      <name>OpenRobotics/MetalCabinet_6</name>
      <uri>model://MetalCabinet</uri>
      <pose>21.687717553019652 -6.425674654473364 0.0 0 0 -0.0244</pose>
      <static>True</static>
    </include>
    <include>
      <name>OpenRobotics/Drawer_3</name>
      <uri>model://Drawer</uri>
      <pose>19.808961801709213 -9.023447216132748 0.0 0 0 1.5708</pose>
      <static>True</static>
    </include>
    <include>
      <name>OpenRobotics/Drawer_4</name>
      <uri>model://Drawer</uri>
      <pose>19.808961801709213 -9.44867749105637 0.0 0 0 1.5708</pose>
      <static>True</static>
    </include>
    <include>
      <name>trash_ingestor</name>
      <uri>model://TeleportIngestor</uri>
      <pose>16.507715078359277 -0.8042220166379742 0.805 0 0 1.5708</pose>
      <static>True</static>
    </include>
    <include>
      <name>trash_room_bin_1</name>
      <uri>model://TrashBin</uri>
      <pose>16.084440333 -0.550257171 0.0 0 0 1.5708</pose>
      <static>True</static>
    </include>
    <include>
      <name>trash_room_bin_2</name>
      <uri>model://TrashBin</uri>
      <pose>16.930989824 -0.550257171 0.0 0 0 1.5708</pose>
      <static>True</static>
    </include>
    <model name="trash_room_floor_box">
      <static>true</static>
      <link name="floor">
        <visual name="visual"><pose>15.099944 -1.409246 -0.025 0 0 0</pose><geometry><box><size>6.60 2.48 0.05</size></box></geometry><material><ambient>0.42 0.43 0.42 1</ambient><diffuse>0.42 0.43 0.42 1</diffuse></material></visual>
        <collision name="collision"><pose>15.099944 -1.409246 -0.025 0 0 0</pose><geometry><box><size>6.60 2.48 0.05</size></box></geometry></collision>
      </link>
    </model>
    <model name="trash_room_box_walls">
      <static>true</static>
      <link name="walls">
        <visual name="right_wall_visual"><pose>17.776 -1.1851695 1.25 0 0 0</pose><geometry><box><size>0.12 2.03 2.5</size></box></geometry><material><ambient>0.88 0.88 0.82 1</ambient><diffuse>0.88 0.88 0.82 1</diffuse></material></visual>
        <collision name="right_wall_collision"><pose>17.776 -1.1851695 1.25 0 0 0</pose><geometry><box><size>0.12 2.03 2.5</size></box></geometry></collision>
        <visual name="top_wall_visual"><pose>16.507715 -0.16931 1.25 0 0 0</pose><geometry><box><size>2.54 0.12 2.5</size></box></geometry><material><ambient>0.88 0.88 0.82 1</ambient><diffuse>0.88 0.88 0.82 1</diffuse></material></visual>
        <collision name="top_wall_collision"><pose>16.507715 -0.16931 1.25 0 0 0</pose><geometry><box><size>2.54 0.12 2.5</size></box></geometry></collision>
        <visual name="bottom_wall_visual"><pose>16.507715 -2.201029 1.25 0 0 0</pose><geometry><box><size>2.54 0.12 2.5</size></box></geometry><material><ambient>0.88 0.88 0.82 1</ambient><diffuse>0.88 0.88 0.82 1</diffuse></material></visual>
        <collision name="bottom_wall_collision"><pose>16.507715 -2.201029 1.25 0 0 0</pose><geometry><box><size>2.54 0.12 2.5</size></box></geometry></collision>
        <visual name="left_wall_upper_visual"><pose>15.23943 -0.423275 1.25 0 0 0</pose><geometry><box><size>0.12 0.51 2.5</size></box></geometry><material><ambient>0.88 0.88 0.82 1</ambient><diffuse>0.88 0.88 0.82 1</diffuse></material></visual>
        <!-- Keep the trash room doorway visually clear while avoiding slotcar collision at the narrow entrance. -->
        <visual name="left_wall_lower_visual"><pose>15.23943 -1.862409 1.25 0 0 0</pose><geometry><box><size>0.12 0.68 2.5</size></box></geometry><material><ambient>0.88 0.88 0.82 1</ambient><diffuse>0.88 0.88 0.82 1</diffuse></material></visual>
        <!-- Keep the trash room doorway visually clear while avoiding slotcar collision at the narrow entrance. -->
      </link>
    </model>
    <include>
      <name>tinyRobot1</name>
      <uri>model://TinyRobot</uri>
      <pose>10.433053704916215 -5.5750955876973505 0.0 0 0 1.3286194884563705</pose>
    </include>
    <include>
      <name>tinyRobot2</name>
      <uri>model://TinyRobot</uri>
      <pose>20.423692180237488 -5.312098057266895 0.0 0 0 -0.7123881023886214</pose>
    </include>
    <model name="main_door">
      <pose>13.131950836046645 -2.579487092649509 0.0 0 0 -3.120269390429785</pose>
      <link name="right">
        <pose>0.473864332736097 0 1.11 0 0 0</pose>
        <visual name="right_visual">
          <geometry>
            <box>
              <size>0.937728665472194 0.03 2.2</size>
            </box>
          </geometry>
          <material>
            <ambient>0.5 0.25 0 0.6</ambient>
            <diffuse>0.5 0.25 0 0.6</diffuse>
          </material>
        </visual>
        <!-- Collision disabled for this demo route; the visual door remains. -->
        <inertial>
          <mass>50.0</mass>
          <inertia>
            <ixx>20.17041666666667</ixx>
            <iyy>23.83056270853443</iyy>
            <izz>3.6676460418677586</izz>
          </inertia>
        </inertial>
      </link>
      <joint name="right_joint" type="revolute">
        <parent>world</parent>
        <child>right</child>
        <axis>
          <xyz>0 0 -1</xyz>
          <limit>
            <lower>0</lower>
            <upper>1.57</upper>
          </limit>
        </axis>
        <pose>0.473864332736097 0 0 0 0 0</pose>
      </joint>
      <link name="left">
        <pose>-0.473864332736097 0 1.11 0 0 0</pose>
        <visual name="left_visual">
          <geometry>
            <box>
              <size>0.937728665472194 0.03 2.2</size>
            </box>
          </geometry>
          <material>
            <ambient>0.5 0.25 0 0.6</ambient>
            <diffuse>0.5 0.25 0 0.6</diffuse>
          </material>
        </visual>
        <!-- Collision disabled for this demo route; the visual door remains. -->
        <inertial>
          <mass>50.0</mass>
          <inertia>
            <ixx>20.17041666666667</ixx>
            <iyy>23.83056270853443</iyy>
            <izz>3.6676460418677586</izz>
          </inertia>
        </inertial>
      </link>
      <joint name="left_joint" type="revolute">
        <parent>world</parent>
        <child>left</child>
        <axis>
          <xyz>0 0 -1</xyz>
          <limit>
            <lower>-1.57</lower>
            <upper>0</upper>
          </limit>
        </axis>
        <pose>-0.473864332736097 0 0 0 0 0</pose>
      </joint>
      <plugin name="door" filename="libdoor.so">
        <v_max_door>1.5</v_max_door>
        <a_max_door>1.0</a_max_door>
        <a_nom_door>0.6</a_nom_door>
        <dx_min_door>0.01</dx_min_door>
        <f_max_door>500.0</f_max_door>
        <door name="main_door" type="DoubleSwingDoor" left_joint_name="left_joint" right_joint_name="right_joint" />
      </plugin>
    </model>
    <model name="coe_door">
      <pose>8.077686357313898 -5.898342045416362 0.0 0 0 1.1560010438234292</pose>
      <link name="right">
        <pose>0 0 1.11 0 0 0</pose>
        <visual name="right_visual">
          <geometry>
            <box>
              <size>0.8766026166317483 0.03 2.2</size>
            </box>
          </geometry>
          <material>
            <ambient>0.5 0.25 0 0.6</ambient>
            <diffuse>0.5 0.25 0 0.6</diffuse>
          </material>
        </visual>
        <collision name="right_collision">
          <geometry>
            <box>
              <size>0.8766026166317483 0.03 2.2</size>
            </box>
          </geometry>
          <surface>
            <contact>
              <collide_bitmask>0x02</collide_bitmask>
            </contact>
          </surface>
        </collision>
        <inertial>
          <mass>50.0</mass>
          <inertia>
            <ixx>20.17041666666667</ixx>
            <iyy>23.36846728119012</iyy>
            <izz>3.20555061452345</izz>
          </inertia>
        </inertial>
      </link>
      <joint name="right_joint" type="revolute">
        <parent>world</parent>
        <child>right</child>
        <axis>
          <xyz>0 0 -1</xyz>
          <limit>
            <lower>0</lower>
            <upper>1.57</upper>
          </limit>
        </axis>
        <pose>0.44330130831587417 0 0 0 0 0</pose>
      </joint>
      <plugin name="door" filename="libdoor.so">
        <v_max_door>1.5</v_max_door>
        <a_max_door>1.0</a_max_door>
        <a_nom_door>0.6</a_nom_door>
        <dx_min_door>0.01</dx_min_door>
        <f_max_door>500.0</f_max_door>
        <door name="coe_door" type="SwingDoor" left_joint_name="empty_joint" right_joint_name="right_joint" />
      </plugin>
    </model>
    <model name="hardware_door">
      <pose>19.450062912168402 -10.319158936370446 0.0 0 0 -1.5760607387686447</pose>
      <link name="right">
        <pose>0 0 1.11 0 0 0</pose>
        <visual name="right_visual">
          <geometry>
            <box>
              <size>0.8792617700206885 0.03 2.2</size>
            </box>
          </geometry>
          <material>
            <ambient>0.5 0.25 0 0.6</ambient>
            <diffuse>0.5 0.25 0 0.6</diffuse>
          </material>
        </visual>
        <collision name="right_collision">
          <geometry>
            <box>
              <size>0.8792617700206885 0.03 2.2</size>
            </box>
          </geometry>
          <surface>
            <contact>
              <collide_bitmask>0x02</collide_bitmask>
            </contact>
          </surface>
        </collision>
        <inertial>
          <mass>50.0</mass>
          <inertia>
            <ixx>20.17041666666667</ixx>
            <iyy>23.387921917582982</iyy>
            <izz>3.225005250916309</izz>
          </inertia>
        </inertial>
      </link>
      <joint name="right_joint" type="revolute">
        <parent>world</parent>
        <child>right</child>
        <axis>
          <xyz>0 0 -1</xyz>
          <limit>
            <lower>0</lower>
            <upper>1.57</upper>
          </limit>
        </axis>
        <pose>0.44463088501034426 0 0 0 0 0</pose>
      </joint>
      <plugin name="door" filename="libdoor.so">
        <v_max_door>10.0</v_max_door>
        <a_max_door>6.0</a_max_door>
        <a_nom_door>2.7</a_nom_door>
        <dx_min_door>0.06</dx_min_door>
        <f_max_door>500.0</f_max_door>
        <door name="hardware_door" type="SwingDoor" left_joint_name="empty_joint" right_joint_name="right_joint" />
      </plugin>
    </model>
    <include>
      <name>building_L1</name>
      <uri>model://building_L1</uri>
      <pose>0 0 0.0 0 0 0</pose>
    </include>
    <model name="waypoint_label_pantry">
      <pose>16.84633487483844 -5.404067193990636 0.02 0 0 0</pose>
      <static>true</static>
      <link name="label">
        <visual name="cross_a"><pose>0 0 0 0 0 0.785398</pose><geometry><box><size>0.85 0.12 0.03</size></box></geometry><material><ambient>1 0.9 0.1 1</ambient><diffuse>1 0.9 0.1 1</diffuse></material></visual>
        <visual name="cross_b"><pose>0 0 0 0 0 -0.785398</pose><geometry><box><size>0.85 0.12 0.03</size></box></geometry><material><ambient>1 0.9 0.1 1</ambient><diffuse>1 0.9 0.1 1</diffuse></material></visual>
      </link>
    </model>
    <model name="waypoint_label_hardware_2">
      <pose>20.948248106963362 -7.497347051865536 0.02 0 0 0</pose>
      <static>true</static>
      <link name="label">
        <visual name="cross_a"><pose>0 0 0 0 0 0.785398</pose><geometry><box><size>0.85 0.12 0.03</size></box></geometry><material><ambient>1 0.9 0.1 1</ambient><diffuse>1 0.9 0.1 1</diffuse></material></visual>
        <visual name="cross_b"><pose>0 0 0 0 0 -0.785398</pose><geometry><box><size>0.85 0.12 0.03</size></box></geometry><material><ambient>1 0.9 0.1 1</ambient><diffuse>1 0.9 0.1 1</diffuse></material></visual>
      </link>
    </model>
    <model name="waypoint_label_coe">
      <pose>5.346484897599354 -4.976813665783051 0.02 0 0 0</pose>
      <static>true</static>
      <link name="label">
        <visual name="cross_a"><pose>0 0 0 0 0 0.785398</pose><geometry><box><size>0.85 0.12 0.03</size></box></geometry><material><ambient>1 0.9 0.1 1</ambient><diffuse>1 0.9 0.1 1</diffuse></material></visual>
        <visual name="cross_b"><pose>0 0 0 0 0 -0.785398</pose><geometry><box><size>0.85 0.12 0.03</size></box></geometry><material><ambient>1 0.9 0.1 1</ambient><diffuse>1 0.9 0.1 1</diffuse></material></visual>
      </link>
    </model>
    <model name="waypoint_label_trash_room">
      <pose>16.507715078359277 -0.8042220166379742 0.02 0 0 0</pose>
      <static>true</static>
      <link name="label">
        <visual name="cross_a"><pose>0 0 0 0 0 0.785398</pose><geometry><box><size>0.85 0.12 0.03</size></box></geometry><material><ambient>0.95 0.25 0.15 1</ambient><diffuse>0.95 0.25 0.15 1</diffuse></material></visual>
        <visual name="cross_b"><pose>0 0 0 0 0 -0.785398</pose><geometry><box><size>0.85 0.12 0.03</size></box></geometry><material><ambient>0.95 0.25 0.15 1</ambient><diffuse>0.95 0.25 0.15 1</diffuse></material></visual>
      </link>
    </model>
    <model name="waypoint_label_patrol_A1">
      <pose>10.086146188918223 -6.979436538645566 0.02 0 0 0</pose>
      <static>true</static>
      <link name="label">
        <visual name="cross_a"><pose>0 0 0 0 0 0.785398</pose><geometry><box><size>0.85 0.12 0.03</size></box></geometry><material><ambient>0.1 0.6 1 1</ambient><diffuse>0.1 0.6 1 1</diffuse></material></visual>
        <visual name="cross_b"><pose>0 0 0 0 0 -0.785398</pose><geometry><box><size>0.85 0.12 0.03</size></box></geometry><material><ambient>0.1 0.6 1 1</ambient><diffuse>0.1 0.6 1 1</diffuse></material></visual>
      </link>
    </model>
    <model name="waypoint_label_patrol_B">
      <pose>7.988303429285765 -10.780257513236124 0.02 0 0 0</pose>
      <static>true</static>
      <link name="label">
        <visual name="cross_a"><pose>0 0 0 0 0 0.785398</pose><geometry><box><size>0.85 0.12 0.03</size></box></geometry><material><ambient>0.1 0.6 1 1</ambient><diffuse>0.1 0.6 1 1</diffuse></material></visual>
        <visual name="cross_b"><pose>0 0 0 0 0 -0.785398</pose><geometry><box><size>0.85 0.12 0.03</size></box></geometry><material><ambient>0.1 0.6 1 1</ambient><diffuse>0.1 0.6 1 1</diffuse></material></visual>
      </link>
    </model>
    <model name="waypoint_label_patrol_C">
      <pose>18.813842874806067 -11.078979432195132 0.02 0 0 0</pose>
      <static>true</static>
      <link name="label">
        <visual name="cross_a"><pose>0 0 0 0 0 0.785398</pose><geometry><box><size>0.85 0.12 0.03</size></box></geometry><material><ambient>0.1 0.6 1 1</ambient><diffuse>0.1 0.6 1 1</diffuse></material></visual>
        <visual name="cross_b"><pose>0 0 0 0 0 -0.785398</pose><geometry><box><size>0.85 0.12 0.03</size></box></geometry><material><ambient>0.1 0.6 1 1</ambient><diffuse>0.1 0.6 1 1</diffuse></material></visual>
      </link>
    </model>
    <model name="waypoint_label_patrol_D1">
      <pose>16.85582469463477 -6.881363780090288 0.02 0 0 0</pose>
      <static>true</static>
      <link name="label">
        <visual name="cross_a"><pose>0 0 0 0 0 0.785398</pose><geometry><box><size>0.85 0.12 0.03</size></box></geometry><material><ambient>0.1 0.6 1 1</ambient><diffuse>0.1 0.6 1 1</diffuse></material></visual>
        <visual name="cross_b"><pose>0 0 0 0 0 -0.785398</pose><geometry><box><size>0.85 0.12 0.03</size></box></geometry><material><ambient>0.1 0.6 1 1</ambient><diffuse>0.1 0.6 1 1</diffuse></material></visual>
      </link>
    </model>
    <model name="waypoint_label_patrol_A2">
      <pose>18.949764861112804 -4.039082328888211 0.02 0 0 0</pose>
      <static>true</static>
      <link name="label">
        <visual name="cross_a"><pose>0 0 0 0 0 0.785398</pose><geometry><box><size>0.85 0.12 0.03</size></box></geometry><material><ambient>0.2 0.8 0.35 1</ambient><diffuse>0.2 0.8 0.35 1</diffuse></material></visual>
        <visual name="cross_b"><pose>0 0 0 0 0 -0.785398</pose><geometry><box><size>0.85 0.12 0.03</size></box></geometry><material><ambient>0.2 0.8 0.35 1</ambient><diffuse>0.2 0.8 0.35 1</diffuse></material></visual>
      </link>
    </model>
    <model name="waypoint_label_patrol_D2">
      <pose>10.247854072726847 -3.09205587858002 0.02 0 0 0</pose>
      <static>true</static>
      <link name="label">
        <visual name="cross_a"><pose>0 0 0 0 0 0.785398</pose><geometry><box><size>0.85 0.12 0.03</size></box></geometry><material><ambient>0.2 0.8 0.35 1</ambient><diffuse>0.2 0.8 0.35 1</diffuse></material></visual>
        <visual name="cross_b"><pose>0 0 0 0 0 -0.785398</pose><geometry><box><size>0.85 0.12 0.03</size></box></geometry><material><ambient>0.2 0.8 0.35 1</ambient><diffuse>0.2 0.8 0.35 1</diffuse></material></visual>
      </link>
    </model>
    <rmf_charger_waypoints name="charger_waypoints">
      <rmf_vertex name="tinyRobot1_charger" x="10.433053704916215" y="-5.5750955876973505" level="L1" />
      <rmf_vertex name="tinyRobot2_charger" x="20.423692180237488" y="-5.312098057266895" level="L1" />
    </rmf_charger_waypoints>
  </world>
</sdf>


